Workbook

Sheet Summary
B1: Sharpe and Sortino
B2: Master Error Check Cell | D2: =+'Error Checking'!B2 -> 0
B4: Actual / Forecast | D4: Actual | E4: Actual | F4: Actual | G4: Actual | H4: Actual | I4: Actual | J4: Forecast | K4: Forecast | L4: Forecast | M4: Forecast | N4: Forecast | O4: Forecast | P4: Forecast | Q4: Forecast | R4: Forecast | S4: Forecast | T4: Forecast | U4: Forecast | V4: Forecast
B5: Week Number | D5: 1 | E5: 2 | F5: 3 | G5: 4 | H5: 5 | I5: 6 | J5: 7 | K5: 8 | L5: 9 | M5: 10 | N5: 11 | O5: 12 | P5: 13 | Q5: 14 | R5: 15 | S5: 16 | T5: 17 | U5: 18 | V5: 19
B6: Week Beginning | D6: =+D7-6 -> 45221 | E6: =+E7-6 -> 45228 | F6: =+F7-6 -> 45235 | G6: =+G7-6 -> 45242 | H6: =+H7-6 -> 45249 | I6: =+I7-6 -> 45256 | J6: =+J7-6 -> 45263 | K6: =+K7-6 -> 45270 | ... V6: =+V7-6 -> 45347
B7: Week Ending | D7: =+E6-1 -> 45227 | E7: =+F6-1 -> 45234 | F7: =+G6-1 -> 45241 | G7: =+H6-1 -> 45248 | H7: =+I6-1 -> 45255 | I7: =+J6-1 -> 45262 | J7: =+K6-1 -> 45269 | K7: =+L6-1 -> 45276 | ... U7: =+V6-1 -> 45346 | V7: =MAX('Forecast 1'!7:7) -> 45353
B9: Cash Balance
B10: Beginning Cash | D10: =IF($B10='Forecast 1'!$B10,INDEX('Forecast 1'!$1:$1048576,MATCH('Forecast 1'!$B10,'Forecast 1'!$B:$B,0),MATCH('Forecast 1'!D$7,'Forecast 1'!$7:$7,0)),"Mismatch") -> 345580 | E10: =+D12 -> 210210 | F10: =+E12 -> 174090 | G10: =+F12 -> 239110 | H10: =+G12 -> 43360 | I10: =+H12 -> 325260 | J10: =+I12 -> 215160 | K10: =+J12 -> 112041.67 | L10: =+K12 -> 156995.28 | ... V10: =+U12 -> 580273.04
B11: Change in Cash | D11: =+D60 -> -135370 | E11: =+E60 -> -36120 | F11: =+F60 -> 65020 | G11: =+G60 -> -195750 | H11: =+H60 -> 281900 | I11: =+I60 -> -110100 | J11: =+J60 -> -103118.33 | K11: =+K60 -> 44953.611 | ... V11: =+V60 -> -289083.47
B12: Ending Cash | D12: =SUM(D10:D11) -> 210210 | E12: =SUM(E10:E11) -> 174090 | F12: =SUM(F10:F11) -> 239110 | G12: =SUM(G10:G11) -> 43360 | H12: =SUM(H10:H11) -> 325260 | I12: =SUM(I10:I11) -> 215160 | J12: =SUM(J10:J11) -> 112041.67 | K12: =SUM(K10:K11) -> 156995.28 | ... V12: =SUM(V10:V11) -> 291189.57
B13: Per Bank Statement | D13: =IF($B13='Forecast 1'!$B13,INDEX('Forecast 1'!$1:$1048576,MATCH('Forecast 1'!$B13,'Forecast 1'!$B:$B,0),MATCH('Forecast 1'!D$7,'Forecast 1'!$7:$7,0)),"Mismatch") -> 210210 | E13: =IF($B13='Forecast 1'!$B13,INDEX('Forecast 1'!$1:$1048576,MATCH('Forecast 1'!$B13,'Forecast 1'!$B:$B,0),MATCH('Forecast 1'!E$7,'Forecast 1'!$7:$7,0)),"Mismatch") -> 174090 | F13: =IF($B13='Forecast 1'!$B13,INDEX('Forecast 1'!$1:$1048576,MATCH('Forecast 1'!$B13,'Forecast 1'!$B:$B,0),MATCH('Forecast 1'!F$7,'Forecast 1'!$7:$7,0)),"Mismatch") -> 239110 | G13: =IF($B13='Forecast 1'!$B13,INDEX('Forecast 1'!$1:$1048576,MATCH('Forecast 1'!$B13,'Forecast 1'!$B:$B,0),MATCH('Forecast 1'!G$7,'Forecast 1'!$7:$7,0)),"Mismatch") -> 43360 | H13: =IF($B13='Forecast 1'!$B13,INDEX('Forecast 1'!$1:$1048576,MATCH('Forecast 1'!$B13,'Forecast 1'!$B:$B,0),MATCH('Forecast 1'!H$7,'Forecast 1'!$7:$7,0)),"Mismatch") -> 325260 | I13: =IF($B13='Forecast 1'!$B13,INDEX('Forecast 1'!$1:$1048576,MATCH('Forecast 1'!$B13,'Forecast 1'!$B:$B,0),MATCH('Forecast 1'!I$7,'Forecast 1'!$7:$7,0)),"Mismatch") -> 215160 | J13: =IF($B13='Forecast 1'!$B13,INDEX('Forecast 1'!$1:$1048576,MATCH('Forecast 1'!$B13,'Forecast 1'!$B:$B,0),MATCH('Forecast 1'!J$7,'Forecast 1'!$7:$7,0)),"Mismatch") -> 0 | K13: =IF($B13='Forecast 1'!$B13,INDEX('Forecast 1'!$1:$1048576,MATCH('Forecast 1'!$B13,'Forecast 1'!$B:$B,0),MATCH('Forecast 1'!K$7,'Forecast 1'!$7:$7,0)),"Mismatch") -> 0 | ... V13: =IF($B13='Forecast 1'!$B13,INDEX('Forecast 1'!$1:$1048576,MATCH('Forecast 1'!$B13,'Forecast 1'!$B:$B,0),MATCH('Forecast 1'!V$7,'Forecast 1'!$7:$7,0)),"Mismatch") -> 0
B14: Double-Check | D14: =IF(D4="Forecast",0,D13-D12) -> 0 | E14: =IF(E4="Forecast",0,E13-E12) -> 0 | F14: =IF(F4="Forecast",0,F13-F12) -> 0 | G14: =IF(G4="Forecast",0,G13-G12) -> 0 | H14: =IF(H4="Forecast",0,H13-H12) -> 0 | I14: =IF(I4="Forecast",0,I13-I12) -> 0 | J14: =IF(J4="Forecast",0,J13-J12) -> 0 | K14: =IF(K4="Forecast",0,K13-K12) -> 0 | ... V14: =IF(V4="Forecast",0,V13-V12) -> 0
B15: Last Week's Forecast | D15: =IF($B15='Forecast 1'!$B15,INDEX('Forecast 1'!$1:$1048576,MATCH('Forecast 1'!$B15,'Forecast 1'!$B:$B,0),MATCH('Forecast 1'!D$7,'Forecast 1'!$7:$7,0)),"Mismatch") -> 0 | E15: =IF($B15='Forecast 1'!$B15,INDEX('Forecast 1'!$1:$1048576,MATCH('Forecast 1'!$B15,'Forecast 1'!$B:$B,0),MATCH('Forecast 1'!E$7,'Forecast 1'!$7:$7,0)),"Mismatch") -> 0 | F15: =IF($B15='Forecast 1'!$B15,INDEX('Forecast 1'!$1:$1048576,MATCH('Forecast 1'!$B15,'Forecast 1'!$B:$B,0),MATCH('Forecast 1'!F$7,'Forecast 1'!$7:$7,0)),"Mismatch") -> 0 | G15: =IF($B15='Forecast 1'!$B15,INDEX('Forecast 1'!$1:$1048576,MATCH('Forecast 1'!$B15,'Forecast 1'!$B:$B,0),MATCH('Forecast 1'!G$7,'Forecast 1'!$7:$7,0)),"Mismatch") -> 0 | H15: =IF($B15='Forecast 1'!$B15,INDEX('Forecast 1'!$1:$1048576,MATCH('Forecast 1'!$B15,'Forecast 1'!$B:$B,0),MATCH('Forecast 1'!H$7,'Forecast 1'!$7:$7,0)),"Mismatch") -> 0 | I15: =IF($B15='Forecast 1'!$B15,INDEX('Forecast 1'!$1:$1048576,MATCH('Forecast 1'!$B15,'Forecast 1'!$B:$B,0),MATCH('Forecast 1'!I$7,'Forecast 1'!$7:$7,0)),"Mismatch") -> 0 | J15: =IF($B15='Forecast 1'!$B15,INDEX('Forecast 1'!$1:$1048576,MATCH('Forecast 1'!$B15,'Forecast 1'!$B:$B,0),MATCH('Forecast 1'!J$7,'Forecast 1'!$7:$7,0)),"Mismatch") -> 0 | K15: =IF($B15='Forecast 1'!$B15,INDEX('Forecast 1'!$1:$1048576,MATCH('Forecast 1'!$B15,'Forecast 1'!$B:$B,0),MATCH('Forecast 1'!K$7,'Forecast 1'!$7:$7,0)),"Mismatch") -> 0 | ... V15: =IF($B15='Forecast 1'!$B15,INDEX('Forecast 1'!$1:$1048576,MATCH('Forecast 1'!$B15,'Forecast 1'!$B:$B,0),MATCH('Forecast 1'!V$7,'Forecast 1'!$7:$7,0)),"Mismatch") -> 0
B17: Cash Inflows
B18: Invoice Revenue Receipts | D18: =IF($B18='Forecast 1'!$B18,INDEX('Forecast 1'!$1:$1048576,MATCH('Forecast 1'!$B18,'Forecast 1'!$B:$B,0),MATCH('Forecast 1'!D$7,'Forecast 1'!$7:$7,0)),"Mismatch") -> 0 | E18: =IF($B18='Forecast 1'!$B18,INDEX('Forecast 1'!$1:$1048576,MATCH('Forecast 1'!$B18,'Forecast 1'!$B:$B,0),MATCH('Forecast 1'!E$7,'Forecast 1'!$7:$7,0)),"Mismatch") -> 372100 | F18: =IF($B18='Forecast 1'!$B18,INDEX('Forecast 1'!$1:$1048576,MATCH('Forecast 1'!$B18,'Forecast 1'!$B:$B,0),MATCH('Forecast 1'!F$7,'Forecast 1'!$7:$7,0)),"Mismatch") -> 210150 | G18: =IF($B18='Forecast 1'!$B18,INDEX('Forecast 1'!$1:$1048576,MATCH('Forecast 1'!$B18,'Forecast 1'!$B:$B,0),MATCH('Forecast 1'!G$7,'Forecast 1'!$7:$7,0)),"Mismatch") -> 0 | H18: =IF($B18='Forecast 1'!$B18,INDEX('Forecast 1'!$1:$1048576,MATCH('Forecast 1'!$B18,'Forecast 1'!$B:$B,0),MATCH('Forecast 1'!H$7,'Forecast 1'!$7:$7,0)),"Mismatch") -> 361430 | I18: =IF($B18='Forecast 1'!$B18,INDEX('Forecast 1'!$1:$1048576,MATCH('Forecast 1'!$B18,'Forecast 1'!$B:$B,0),MATCH('Forecast 1'!I$7,'Forecast 1'!$7:$7,0)),"Mismatch") -> 68440 | J18: =IF($B18='Forecast 1'!$B18,INDEX('Forecast 1'!$1:$1048576,MATCH('Forecast 1'!$B18,'Forecast 1'!$B:$B,0),MATCH('Forecast 1'!J$7,'Forecast 1'!$7:$7,0)),"Mismatch") -> 330000 | K18: =IF($B18='Forecast 1'!$B18,INDEX('Forecast 1'!$1:$1048576,MATCH('Forecast 1'!$B18,'Forecast 1'!$B:$B,0),MATCH('Forecast 1'!K$7,'Forecast 1'!$7:$7,0)),"Mismatch") -> 120000 | ... V18: =IF($B18='Forecast 1'!$B18,INDEX('Forecast 1'!$1:$1048576,MATCH('Forecast 1'!$B18,'Forecast 1'!$B:$B,0),MATCH('Forecast 1'!V$7,'Forecast 1'!$7:$7,0)),"Mismatch") -> 0
B19: Other Receipts | D19: =IF($B19='Forecast 1'!$B19,INDEX('Forecast 1'!$1:$1048576,MATCH('Forecast 1'!$B19,'Forecast 1'!$B:$B,0),MATCH('Forecast 1'!D$7,'Forecast 1'!$7:$7,0)),"Mismatch") -> 0 | E19: =IF($B19='Forecast 1'!$B19,INDEX('Forecast 1'!$1:$1048576,MATCH('Forecast 1'!$B19,'Forecast 1'!$B:$B,0),MATCH('Forecast 1'!E$7,'Forecast 1'!$7:$7,0)),"Mismatch") -> 0 | F19: =IF($B19='Forecast 1'!$B19,INDEX('Forecast 1'!$1:$1048576,MATCH('Forecast 1'!$B19,'Forecast 1'!$B:$B,0),MATCH('Forecast 1'!F$7,'Forecast 1'!$7:$7,0)),"Mismatch") -> 0 | G19: =IF($B19='Forecast 1'!$B19,INDEX('Forecast 1'!$1:$1048576,MATCH('Forecast 1'!$B19,'Forecast 1'!$B:$B,0),MATCH('Forecast 1'!G$7,'Forecast 1'!$7:$7,0)),"Mismatch") -> 0 | H19: =IF($B19='Forecast 1'!$B19,INDEX('Forecast 1'!$1:$1048576,MATCH('Forecast 1'!$B19,'Forecast 1'!$B:$B,0),MATCH('Forecast 1'!H$7,'Forecast 1'!$7:$7,0)),"Mismatch") -> 0 | I19: =IF($B19='Forecast 1'!$B19,INDEX('Forecast 1'!$1:$1048576,MATCH('Forecast 1'!$B19,'Forecast 1'!$B:$B,0),MATCH('Forecast 1'!I$7,'Forecast 1'!$7:$7,0)),"Mismatch") -> 0 | J19: =IF($B19='Forecast 1'!$B19,INDEX('Forecast 1'!$1:$1048576,MATCH('Forecast 1'!$B19,'Forecast 1'!$B:$B,0),MATCH('Forecast 1'!J$7,'Forecast 1'!$7:$7,0)),"Mismatch") -> 0 | K19: =IF($B19='Forecast 1'!$B19,INDEX('Forecast 1'!$1:$1048576,MATCH('Forecast 1'!$B19,'Forecast 1'!$B:$B,0),MATCH('Forecast 1'!K$7,'Forecast 1'!$7:$7,0)),"Mismatch") -> 0 | ... V19: =IF($B19='Forecast 1'!$B19,INDEX('Forecast 1'!$1:$1048576,MATCH('Forecast 1'!$B19,'Forecast 1'!$B:$B,0),MATCH('Forecast 1'!V$7,'Forecast 1'!$7:$7,0)),"Mismatch") -> 0
B21: Total Cash Inflows | D21: =SUM(D18:D20) -> 0 | E21: =SUM(E18:E20) -> 372100 | F21: =SUM(F18:F20) -> 210150 | G21: =SUM(G18:G20) -> 0 | H21: =SUM(H18:H20) -> 361430 | I21: =SUM(I18:I20) -> 68440 | J21: =SUM(J18:J20) -> 330000 | K21: =SUM(K18:K20) -> 120000 | ... V21: =SUM(V18:V20) -> 0
B23: Operating Cash Outflows
B24: Accounts Payable | D24: =IF($B24='Forecast 1'!$B24,INDEX('Forecast 1'!$1:$1048576,MATCH('Forecast 1'!$B24,'Forecast 1'!$B:$B,0),MATCH('Forecast 1'!D$7,'Forecast 1'!$7:$7,0)),"Mismatch") -> -33620 | E24: =IF($B24='Forecast 1'!$B24,INDEX('Forecast 1'!$1:$1048576,MATCH('Forecast 1'!$B24,'Forecast 1'!$B:$B,0),MATCH('Forecast 1'!E$7,'Forecast 1'!$7:$7,0)),"Mismatch") -> -83210 | F24: =IF($B24='Forecast 1'!$B24,INDEX('Forecast 1'!$1:$1048576,MATCH('Forecast 1'!$B24,'Forecast 1'!$B:$B,0),MATCH('Forecast 1'!F$7,'Forecast 1'!$7:$7,0)),"Mismatch") -> -69810 | G24: =IF($B24='Forecast 1'!$B24,INDEX('Forecast 1'!$1:$1048576,MATCH('Forecast 1'!$B24,'Forecast 1'!$B:$B,0),MATCH('Forecast 1'!G$7,'Forecast 1'!$7:$7,0)),"Mismatch") -> -40140 | H24: =IF($B24='Forecast 1'!$B24,INDEX('Forecast 1'!$1:$1048576,MATCH('Forecast 1'!$B24,'Forecast 1'!$B:$B,0),MATCH('Forecast 1'!H$7,'Forecast 1'!$7:$7,0)),"Mismatch") -> -18680 | I24: =IF($B24='Forecast 1'!$B24,INDEX('Forecast 1'!$1:$1048576,MATCH('Forecast 1'!$B24,'Forecast 1'!$B:$B,0),MATCH('Forecast 1'!I$7,'Forecast 1'!$7:$7,0)),"Mismatch") -> -88580 | J24: =IF($B24='Forecast 1'!$B24,INDEX('Forecast 1'!$1:$1048576,MATCH('Forecast 1'!$B24,'Forecast 1'!$B:$B,0),MATCH('Forecast 1'!J$7,'Forecast 1'!$7:$7,0)),"Mismatch") -> -800 | K24: =IF($B24='Forecast 1'!$B24,INDEX('Forecast 1'!$1:$1048576,MATCH('Forecast 1'!$B24,'Forecast 1'!$B:$B,0),MATCH('Forecast 1'!K$7,'Forecast 1'!$7:$7,0)),"Mismatch") -> -1800 | ... V24: =IF($B24='Forecast 1'!$B24,INDEX('Forecast 1'!$1:$1048576,MATCH('Forecast 1'!$B24,'Forecast 1'!$B:$B,0),MATCH('Forecast 1'!V$7,'Forecast 1'!$7:$7,0)),"Mismatch") -> 0
B25: Credit Cards | D25: =IF($B25='Forecast 1'!$B25,INDEX('Forecast 1'!$1:$1048576,MATCH('Forecast 1'!$B25,'Forecast 1'!$B:$B,0),MATCH('Forecast 1'!D$7,'Forecast 1'!$7:$7,0)),"Mismatch") -> 0 | E25: =IF($B25='Forecast 1'!$B25,INDEX('Forecast 1'!$1:$1048576,MATCH('Forecast 1'!$B25,'Forecast 1'!$B:$B,0),MATCH('Forecast 1'!E$7,'Forecast 1'!$7:$7,0)),"Mismatch") -> -194090 | F25: =IF($B25='Forecast 1'!$B25,INDEX('Forecast 1'!$1:$1048576,MATCH('Forecast 1'!$B25,'Forecast 1'!$B:$B,0),MATCH('Forecast 1'!F$7,'Forecast 1'!$7:$7,0)),"Mismatch") -> 0 | G25: =IF($B25='Forecast 1'!$B25,INDEX('Forecast 1'!$1:$1048576,MATCH('Forecast 1'!$B25,'Forecast 1'!$B:$B,0),MATCH('Forecast 1'!G$7,'Forecast 1'!$7:$7,0)),"Mismatch") -> -100000 | H25: =IF($B25='Forecast 1'!$B25,INDEX('Forecast 1'!$1:$1048576,MATCH('Forecast 1'!$B25,'Forecast 1'!$B:$B,0),MATCH('Forecast 1'!H$7,'Forecast 1'!$7:$7,0)),"Mismatch") -> 0 | I25: =IF($B25='Forecast 1'!$B25,INDEX('Forecast 1'!$1:$1048576,MATCH('Forecast 1'!$B25,'Forecast 1'!$B:$B,0),MATCH('Forecast 1'!I$7,'Forecast 1'!$7:$7,0)),"Mismatch") -> -32000 | J25: =IF($B25='Forecast 1'!$B25,INDEX('Forecast 1'!$1:$1048576,MATCH('Forecast 1'!$B25,'Forecast 1'!$B:$B,0),MATCH('Forecast 1'!J$7,'Forecast 1'!$7:$7,0)),"Mismatch") -> -350000 | K25: =IF($B25='Forecast 1'!$B25,INDEX('Forecast 1'!$1:$1048576,MATCH('Forecast 1'!$B25,'Forecast 1'!$B:$B,0),MATCH('Forecast 1'!K$7,'Forecast 1'!$7:$7,0)),"Mismatch") -> 0 | ... V25: =IF($B25='Forecast 1'!$B25,INDEX('Forecast 1'!$1:$1048576,MATCH('Forecast 1'!$B25,'Forecast 1'!$B:$B,0),MATCH('Forecast 1'!V$7,'Forecast 1'!$7:$7,0)),"Mismatch") -> -210000
B26: Payroll | C26: Trailing 6 Week Average | D26: =IF($B26='Forecast 1'!$B26,INDEX('Forecast 1'!$1:$1048576,MATCH('Forecast 1'!$B26,'Forecast 1'!$B:$B,0),MATCH('Forecast 1'!D$7,'Forecast 1'!$7:$7,0)),"Mismatch") -> -77830 | E26: =IF($B26='Forecast 1'!$B26,INDEX('Forecast 1'!$1:$1048576,MATCH('Forecast 1'!$B26,'Forecast 1'!$B:$B,0),MATCH('Forecast 1'!E$7,'Forecast 1'!$7:$7,0)),"Mismatch") -> -78050 | F26: =IF($B26='Forecast 1'!$B26,INDEX('Forecast 1'!$1:$1048576,MATCH('Forecast 1'!$B26,'Forecast 1'!$B:$B,0),MATCH('Forecast 1'!F$7,'Forecast 1'!$7:$7,0)),"Mismatch") -> -51670 | G26: =IF($B26='Forecast 1'!$B26,INDEX('Forecast 1'!$1:$1048576,MATCH('Forecast 1'!$B26,'Forecast 1'!$B:$B,0),MATCH('Forecast 1'!G$7,'Forecast 1'!$7:$7,0)),"Mismatch") -> -39960 | H26: =IF($B26='Forecast 1'!$B26,INDEX('Forecast 1'!$1:$1048576,MATCH('Forecast 1'!$B26,'Forecast 1'!$B:$B,0),MATCH('Forecast 1'!H$7,'Forecast 1'!$7:$7,0)),"Mismatch") -> -44380 | I26: =IF($B26='Forecast 1'!$B26,INDEX('Forecast 1'!$1:$1048576,MATCH('Forecast 1'!$B26,'Forecast 1'!$B:$B,0),MATCH('Forecast 1'!I$7,'Forecast 1'!$7:$7,0)),"Mismatch") -> -35340 | J26: =IF($B26='Forecast 1'!$B26,INDEX('Forecast 1'!$1:$1048576,MATCH('Forecast 1'!$B26,'Forecast 1'!$B:$B,0),MATCH('Forecast 1'!J$7,'Forecast 1'!$7:$7,0)),"Mismatch") -> -54538.333 | K26: =IF($B26='Forecast 1'!$B26,INDEX('Forecast 1'!$1:$1048576,MATCH('Forecast 1'!$B26,'Forecast 1'!$B:$B,0),MATCH('Forecast 1'!K$7,'Forecast 1'!$7:$7,0)),"Mismatch") -> -50656.389 | ... V26: =IF($B26='Forecast 1'!$B26,INDEX('Forecast 1'!$1:$1048576,MATCH('Forecast 1'!$B26,'Forecast 1'!$B:$B,0),MATCH('Forecast 1'!V$7,'Forecast 1'!$7:$7,0)),"Mismatch") -> -46966.597
B27: Contractors | C27: Enter Manually | D27: =IF($B27='Forecast 1'!$B27,INDEX('Forecast 1'!$1:$1048576,MATCH('Forecast 1'!$B27,'Forecast 1'!$B:$B,0),MATCH('Forecast 1'!D$7,'Forecast 1'!$7:$7,0)),"Mismatch") -> 0 | E27: =IF($B27='Forecast 1'!$B27,INDEX('Forecast 1'!$1:$1048576,MATCH('Forecast 1'!$B27,'Forecast 1'!$B:$B,0),MATCH('Forecast 1'!E$7,'Forecast 1'!$7:$7,0)),"Mismatch") -> 0 | F27: =IF($B27='Forecast 1'!$B27,INDEX('Forecast 1'!$1:$1048576,MATCH('Forecast 1'!$B27,'Forecast 1'!$B:$B,0),MATCH('Forecast 1'!F$7,'Forecast 1'!$7:$7,0)),"Mismatch") -> 0 | G27: =IF($B27='Forecast 1'!$B27,INDEX('Forecast 1'!$1:$1048576,MATCH('Forecast 1'!$B27,'Forecast 1'!$B:$B,0),MATCH('Forecast 1'!G$7,'Forecast 1'!$7:$7,0)),"Mismatch") -> 0 | H27: =IF($B27='Forecast 1'!$B27,INDEX('Forecast 1'!$1:$1048576,MATCH('Forecast 1'!$B27,'Forecast 1'!$B:$B,0),MATCH('Forecast 1'!H$7,'Forecast 1'!$7:$7,0)),"Mismatch") -> 0 | I27: =IF($B27='Forecast 1'!$B27,INDEX('Forecast 1'!$1:$1048576,MATCH('Forecast 1'!$B27,'Forecast 1'!$B:$B,0),MATCH('Forecast 1'!I$7,'Forecast 1'!$7:$7,0)),"Mismatch") -> 0 | J27: =IF($B27='Forecast 1'!$B27,INDEX('Forecast 1'!$1:$1048576,MATCH('Forecast 1'!$B27,'Forecast 1'!$B:$B,0),MATCH('Forecast 1'!J$7,'Forecast 1'!$7:$7,0)),"Mismatch") -> 0 | K27: =IF($B27='Forecast 1'!$B27,INDEX('Forecast 1'!$1:$1048576,MATCH('Forecast 1'!$B27,'Forecast 1'!$B:$B,0),MATCH('Forecast 1'!K$7,'Forecast 1'!$7:$7,0)),"Mismatch") -> 0 | ... V27: =IF($B27='Forecast 1'!$B27,INDEX('Forecast 1'!$1:$1048576,MATCH('Forecast 1'!$B27,'Forecast 1'!$B:$B,0),MATCH('Forecast 1'!V$7,'Forecast 1'!$7:$7,0)),"Mismatch") -> 0
B28: Dues & Subscriptions | C28: Trailing 6 Week Average | D28: =IF($B28='Forecast 1'!$B28,INDEX('Forecast 1'!$1:$1048576,MATCH('Forecast 1'!$B28,'Forecast 1'!$B:$B,0),MATCH('Forecast 1'!D$7,'Forecast 1'!$7:$7,0)),"Mismatch") -> -310 | E28: =IF($B28='Forecast 1'!$B28,INDEX('Forecast 1'!$1:$1048576,MATCH('Forecast 1'!$B28,'Forecast 1'!$B:$B,0),MATCH('Forecast 1'!E$7,'Forecast 1'!$7:$7,0)),"Mismatch") -> -310 | F28: =IF($B28='Forecast 1'!$B28,INDEX('Forecast 1'!$1:$1048576,MATCH('Forecast 1'!$B28,'Forecast 1'!$B:$B,0),MATCH('Forecast 1'!F$7,'Forecast 1'!$7:$7,0)),"Mismatch") -> -310 | G28: =IF($B28='Forecast 1'!$B28,INDEX('Forecast 1'!$1:$1048576,MATCH('Forecast 1'!$B28,'Forecast 1'!$B:$B,0),MATCH('Forecast 1'!G$7,'Forecast 1'!$7:$7,0)),"Mismatch") -> -310 | H28: =IF($B28='Forecast 1'!$B28,INDEX('Forecast 1'!$1:$1048576,MATCH('Forecast 1'!$B28,'Forecast 1'!$B:$B,0),MATCH('Forecast 1'!H$7,'Forecast 1'!$7:$7,0)),"Mismatch") -> -310 | I28: =IF($B28='Forecast 1'!$B28,INDEX('Forecast 1'!$1:$1048576,MATCH('Forecast 1'!$B28,'Forecast 1'!$B:$B,0),MATCH('Forecast 1'!I$7,'Forecast 1'!$7:$7,0)),"Mismatch") -> -310 | J28: =IF($B28='Forecast 1'!$B28,INDEX('Forecast 1'!$1:$1048576,MATCH('Forecast 1'!$B28,'Forecast 1'!$B:$B,0),MATCH('Forecast 1'!J$7,'Forecast 1'!$7:$7,0)),"Mismatch") -> -310 | K28: =IF($B28='Forecast 1'!$B28,INDEX('Forecast 1'!$1:$1048576,MATCH('Forecast 1'!$B28,'Forecast 1'!$B:$B,0),MATCH('Forecast 1'!K$7,'Forecast 1'!$7:$7,0)),"Mismatch") -> -310 | ... V28: =IF($B28='Forecast 1'!$B28,INDEX('Forecast 1'!$1:$1048576,MATCH('Forecast 1'!$B28,'Forecast 1'!$B:$B,0),MATCH('Forecast 1'!V$7,'Forecast 1'!$7:$7,0)),"Mismatch") -> -310
B29: Insurance | C29: Enter Manually | D29: =IF($B29='Forecast 1'!$B29,INDEX('Forecast 1'!$1:$1048576,MATCH('Forecast 1'!$B29,'Forecast 1'!$B:$B,0),MATCH('Forecast 1'!D$7,'Forecast 1'!$7:$7,0)),"Mismatch") -> 0 | E29: =IF($B29='Forecast 1'!$B29,INDEX('Forecast 1'!$1:$1048576,MATCH('Forecast 1'!$B29,'Forecast 1'!$B:$B,0),MATCH('Forecast 1'!E$7,'Forecast 1'!$7:$7,0)),"Mismatch") -> 0 | F29: =IF($B29='Forecast 1'!$B29,INDEX('Forecast 1'!$1:$1048576,MATCH('Forecast 1'!$B29,'Forecast 1'!$B:$B,0),MATCH('Forecast 1'!F$7,'Forecast 1'!$7:$7,0)),"Mismatch") -> 0 | G29: =IF($B29='Forecast 1'!$B29,INDEX('Forecast 1'!$1:$1048576,MATCH('Forecast 1'!$B29,'Forecast 1'!$B:$B,0),MATCH('Forecast 1'!G$7,'Forecast 1'!$7:$7,0)),"Mismatch") -> 0 | H29: =IF($B29='Forecast 1'!$B29,INDEX('Forecast 1'!$1:$1048576,MATCH('Forecast 1'!$B29,'Forecast 1'!$B:$B,0),MATCH('Forecast 1'!H$7,'Forecast 1'!$7:$7,0)),"Mismatch") -> 0 | I29: =IF($B29='Forecast 1'!$B29,INDEX('Forecast 1'!$1:$1048576,MATCH('Forecast 1'!$B29,'Forecast 1'!$B:$B,0),MATCH('Forecast 1'!I$7,'Forecast 1'!$7:$7,0)),"Mismatch") -> 0 | J29: =IF($B29='Forecast 1'!$B29,INDEX('Forecast 1'!$1:$1048576,MATCH('Forecast 1'!$B29,'Forecast 1'!$B:$B,0),MATCH('Forecast 1'!J$7,'Forecast 1'!$7:$7,0)),"Mismatch") -> 0 | K29: =IF($B29='Forecast 1'!$B29,INDEX('Forecast 1'!$1:$1048576,MATCH('Forecast 1'!$B29,'Forecast 1'!$B:$B,0),MATCH('Forecast 1'!K$7,'Forecast 1'!$7:$7,0)),"Mismatch") -> 0 | ... V29: =IF($B29='Forecast 1'!$B29,INDEX('Forecast 1'!$1:$1048576,MATCH('Forecast 1'!$B29,'Forecast 1'!$B:$B,0),MATCH('Forecast 1'!V$7,'Forecast 1'!$7:$7,0)),"Mismatch") -> 0
B30: Lease Payments | C30: Trailing 6 Week Average | D30: =IF($B30='Forecast 1'!$B30,INDEX('Forecast 1'!$1:$1048576,MATCH('Forecast 1'!$B30,'Forecast 1'!$B:$B,0),MATCH('Forecast 1'!D$7,'Forecast 1'!$7:$7,0)),"Mismatch") -> 0 | E30: =IF($B30='Forecast 1'!$B30,INDEX('Forecast 1'!$1:$1048576,MATCH('Forecast 1'!$B30,'Forecast 1'!$B:$B,0),MATCH('Forecast 1'!E$7,'Forecast 1'!$7:$7,0)),"Mismatch") -> -1350 | F30: =IF($B30='Forecast 1'!$B30,INDEX('Forecast 1'!$1:$1048576,MATCH('Forecast 1'!$B30,'Forecast 1'!$B:$B,0),MATCH('Forecast 1'!F$7,'Forecast 1'!$7:$7,0)),"Mismatch") -> 0 | G30: =IF($B30='Forecast 1'!$B30,INDEX('Forecast 1'!$1:$1048576,MATCH('Forecast 1'!$B30,'Forecast 1'!$B:$B,0),MATCH('Forecast 1'!G$7,'Forecast 1'!$7:$7,0)),"Mismatch") -> 0 | H30: =IF($B30='Forecast 1'!$B30,INDEX('Forecast 1'!$1:$1048576,MATCH('Forecast 1'!$B30,'Forecast 1'!$B:$B,0),MATCH('Forecast 1'!H$7,'Forecast 1'!$7:$7,0)),"Mismatch") -> -1350 | I30: =IF($B30='Forecast 1'!$B30,INDEX('Forecast 1'!$1:$1048576,MATCH('Forecast 1'!$B30,'Forecast 1'!$B:$B,0),MATCH('Forecast 1'!I$7,'Forecast 1'!$7:$7,0)),"Mismatch") -> -1350 | J30: =IF($B30='Forecast 1'!$B30,INDEX('Forecast 1'!$1:$1048576,MATCH('Forecast 1'!$B30,'Forecast 1'!$B:$B,0),MATCH('Forecast 1'!J$7,'Forecast 1'!$7:$7,0)),"Mismatch") -> -675 | K30: =IF($B30='Forecast 1'!$B30,INDEX('Forecast 1'!$1:$1048576,MATCH('Forecast 1'!$B30,'Forecast 1'!$B:$B,0),MATCH('Forecast 1'!K$7,'Forecast 1'!$7:$7,0)),"Mismatch") -> -787.5 | ... V30: =IF($B30='Forecast 1'!$B30,INDEX('Forecast 1'!$1:$1048576,MATCH('Forecast 1'!$B30,'Forecast 1'!$B:$B,0),MATCH('Forecast 1'!V$7,'Forecast 1'!$7:$7,0)),"Mismatch") -> -828.39988
B31: Marketing | C31: Trailing 6 Week Average | D31: =IF($B31='Forecast 1'!$B31,INDEX('Forecast 1'!$1:$1048576,MATCH('Forecast 1'!$B31,'Forecast 1'!$B:$B,0),MATCH('Forecast 1'!D$7,'Forecast 1'!$7:$7,0)),"Mismatch") -> 0 | E31: =IF($B31='Forecast 1'!$B31,INDEX('Forecast 1'!$1:$1048576,MATCH('Forecast 1'!$B31,'Forecast 1'!$B:$B,0),MATCH('Forecast 1'!E$7,'Forecast 1'!$7:$7,0)),"Mismatch") -> -1510 | F31: =IF($B31='Forecast 1'!$B31,INDEX('Forecast 1'!$1:$1048576,MATCH('Forecast 1'!$B31,'Forecast 1'!$B:$B,0),MATCH('Forecast 1'!F$7,'Forecast 1'!$7:$7,0)),"Mismatch") -> -1020 | G31: =IF($B31='Forecast 1'!$B31,INDEX('Forecast 1'!$1:$1048576,MATCH('Forecast 1'!$B31,'Forecast 1'!$B:$B,0),MATCH('Forecast 1'!G$7,'Forecast 1'!$7:$7,0)),"Mismatch") -> 0 | H31: =IF($B31='Forecast 1'!$B31,INDEX('Forecast 1'!$1:$1048576,MATCH('Forecast 1'!$B31,'Forecast 1'!$B:$B,0),MATCH('Forecast 1'!H$7,'Forecast 1'!$7:$7,0)),"Mismatch") -> 0 | I31: =IF($B31='Forecast 1'!$B31,INDEX('Forecast 1'!$1:$1048576,MATCH('Forecast 1'!$B31,'Forecast 1'!$B:$B,0),MATCH('Forecast 1'!I$7,'Forecast 1'!$7:$7,0)),"Mismatch") -> -1510 | J31: =IF($B31='Forecast 1'!$B31,INDEX('Forecast 1'!$1:$1048576,MATCH('Forecast 1'!$B31,'Forecast 1'!$B:$B,0),MATCH('Forecast 1'!J$7,'Forecast 1'!$7:$7,0)),"Mismatch") -> -673.33333 | K31: =IF($B31='Forecast 1'!$B31,INDEX('Forecast 1'!$1:$1048576,MATCH('Forecast 1'!$B31,'Forecast 1'!$B:$B,0),MATCH('Forecast 1'!K$7,'Forecast 1'!$7:$7,0)),"Mismatch") -> -785.55556 | ... V31: =IF($B31='Forecast 1'!$B31,INDEX('Forecast 1'!$1:$1048576,MATCH('Forecast 1'!$B31,'Forecast 1'!$B:$B,0),MATCH('Forecast 1'!V$7,'Forecast 1'!$7:$7,0)),"Mismatch") -> -717.21397
B32: Phone & Internet | C32: Enter Manually | D32: =IF($B32='Forecast 1'!$B32,INDEX('Forecast 1'!$1:$1048576,MATCH('Forecast 1'!$B32,'Forecast 1'!$B:$B,0),MATCH('Forecast 1'!D$7,'Forecast 1'!$7:$7,0)),"Mismatch") -> 0 | E32: =IF($B32='Forecast 1'!$B32,INDEX('Forecast 1'!$1:$1048576,MATCH('Forecast 1'!$B32,'Forecast 1'!$B:$B,0),MATCH('Forecast 1'!E$7,'Forecast 1'!$7:$7,0)),"Mismatch") -> 0 | F32: =IF($B32='Forecast 1'!$B32,INDEX('Forecast 1'!$1:$1048576,MATCH('Forecast 1'!$B32,'Forecast 1'!$B:$B,0),MATCH('Forecast 1'!F$7,'Forecast 1'!$7:$7,0)),"Mismatch") -> 0 | G32: =IF($B32='Forecast 1'!$B32,INDEX('Forecast 1'!$1:$1048576,MATCH('Forecast 1'!$B32,'Forecast 1'!$B:$B,0),MATCH('Forecast 1'!G$7,'Forecast 1'!$7:$7,0)),"Mismatch") -> 0 | H32: =IF($B32='Forecast 1'!$B32,INDEX('Forecast 1'!$1:$1048576,MATCH('Forecast 1'!$B32,'Forecast 1'!$B:$B,0),MATCH('Forecast 1'!H$7,'Forecast 1'!$7:$7,0)),"Mismatch") -> 0 | I32: =IF($B32='Forecast 1'!$B32,INDEX('Forecast 1'!$1:$1048576,MATCH('Forecast 1'!$B32,'Forecast 1'!$B:$B,0),MATCH('Forecast 1'!I$7,'Forecast 1'!$7:$7,0)),"Mismatch") -> 0 | J32: =IF($B32='Forecast 1'!$B32,INDEX('Forecast 1'!$1:$1048576,MATCH('Forecast 1'!$B32,'Forecast 1'!$B:$B,0),MATCH('Forecast 1'!J$7,'Forecast 1'!$7:$7,0)),"Mismatch") -> 0 | K32: =IF($B32='Forecast 1'!$B32,INDEX('Forecast 1'!$1:$1048576,MATCH('Forecast 1'!$B32,'Forecast 1'!$B:$B,0),MATCH('Forecast 1'!K$7,'Forecast 1'!$7:$7,0)),"Mismatch") -> 0 | ... V32: =IF($B32='Forecast 1'!$B32,INDEX('Forecast 1'!$1:$1048576,MATCH('Forecast 1'!$B32,'Forecast 1'!$B:$B,0),MATCH('Forecast 1'!V$7,'Forecast 1'!$7:$7,0)),"Mismatch") -> 0
B33: Professional Fees | C33: $5k each Month | D33: =IF($B33='Forecast 1'!$B33,INDEX('Forecast 1'!$1:$1048576,MATCH('Forecast 1'!$B33,'Forecast 1'!$B:$B,0),MATCH('Forecast 1'!D$7,'Forecast 1'!$7:$7,0)),"Mismatch") -> 0 | E33: =IF($B33='Forecast 1'!$B33,INDEX('Forecast 1'!$1:$1048576,MATCH('Forecast 1'!$B33,'Forecast 1'!$B:$B,0),MATCH('Forecast 1'!E$7,'Forecast 1'!$7:$7,0)),"Mismatch") -> -5000 | F33: =IF($B33='Forecast 1'!$B33,INDEX('Forecast 1'!$1:$1048576,MATCH('Forecast 1'!$B33,'Forecast 1'!$B:$B,0),MATCH('Forecast 1'!F$7,'Forecast 1'!$7:$7,0)),"Mismatch") -> 0 | G33: =IF($B33='Forecast 1'!$B33,INDEX('Forecast 1'!$1:$1048576,MATCH('Forecast 1'!$B33,'Forecast 1'!$B:$B,0),MATCH('Forecast 1'!G$7,'Forecast 1'!$7:$7,0)),"Mismatch") -> 0 | H33: =IF($B33='Forecast 1'!$B33,INDEX('Forecast 1'!$1:$1048576,MATCH('Forecast 1'!$B33,'Forecast 1'!$B:$B,0),MATCH('Forecast 1'!H$7,'Forecast 1'!$7:$7,0)),"Mismatch") -> 0 | I33: =IF($B33='Forecast 1'!$B33,INDEX('Forecast 1'!$1:$1048576,MATCH('Forecast 1'!$B33,'Forecast 1'!$B:$B,0),MATCH('Forecast 1'!I$7,'Forecast 1'!$7:$7,0)),"Mismatch") -> 0 | J33: =IF($B33='Forecast 1'!$B33,INDEX('Forecast 1'!$1:$1048576,MATCH('Forecast 1'!$B33,'Forecast 1'!$B:$B,0),MATCH('Forecast 1'!J$7,'Forecast 1'!$7:$7,0)),"Mismatch") -> -5000 | K33: =IF($B33='Forecast 1'!$B33,INDEX('Forecast 1'!$1:$1048576,MATCH('Forecast 1'!$B33,'Forecast 1'!$B:$B,0),MATCH('Forecast 1'!K$7,'Forecast 1'!$7:$7,0)),"Mismatch") -> 0 | ... V33: =IF($B33='Forecast 1'!$B33,INDEX('Forecast 1'!$1:$1048576,MATCH('Forecast 1'!$B33,'Forecast 1'!$B:$B,0),MATCH('Forecast 1'!V$7,'Forecast 1'!$7:$7,0)),"Mismatch") -> -5000
B34: Rent | C34: Enter Manually | D34: =IF($B34='Forecast 1'!$B34,INDEX('Forecast 1'!$1:$1048576,MATCH('Forecast 1'!$B34,'Forecast 1'!$B:$B,0),MATCH('Forecast 1'!D$7,'Forecast 1'!$7:$7,0)),"Mismatch") -> 0 | E34: =IF($B34='Forecast 1'!$B34,INDEX('Forecast 1'!$1:$1048576,MATCH('Forecast 1'!$B34,'Forecast 1'!$B:$B,0),MATCH('Forecast 1'!E$7,'Forecast 1'!$7:$7,0)),"Mismatch") -> 0 | F34: =IF($B34='Forecast 1'!$B34,INDEX('Forecast 1'!$1:$1048576,MATCH('Forecast 1'!$B34,'Forecast 1'!$B:$B,0),MATCH('Forecast 1'!F$7,'Forecast 1'!$7:$7,0)),"Mismatch") -> 0 | G34: =IF($B34='Forecast 1'!$B34,INDEX('Forecast 1'!$1:$1048576,MATCH('Forecast 1'!$B34,'Forecast 1'!$B:$B,0),MATCH('Forecast 1'!G$7,'Forecast 1'!$7:$7,0)),"Mismatch") -> 0 | H34: =IF($B34='Forecast 1'!$B34,INDEX('Forecast 1'!$1:$1048576,MATCH('Forecast 1'!$B34,'Forecast 1'!$B:$B,0),MATCH('Forecast 1'!H$7,'Forecast 1'!$7:$7,0)),"Mismatch") -> 0 | I34: =IF($B34='Forecast 1'!$B34,INDEX('Forecast 1'!$1:$1048576,MATCH('Forecast 1'!$B34,'Forecast 1'!$B:$B,0),MATCH('Forecast 1'!I$7,'Forecast 1'!$7:$7,0)),"Mismatch") -> 0 | J34: =IF($B34='Forecast 1'!$B34,INDEX('Forecast 1'!$1:$1048576,MATCH('Forecast 1'!$B34,'Forecast 1'!$B:$B,0),MATCH('Forecast 1'!J$7,'Forecast 1'!$7:$7,0)),"Mismatch") -> 0 | K34: =IF($B34='Forecast 1'!$B34,INDEX('Forecast 1'!$1:$1048576,MATCH('Forecast 1'!$B34,'Forecast 1'!$B:$B,0),MATCH('Forecast 1'!K$7,'Forecast 1'!$7:$7,0)),"Mismatch") -> 0 | ... V34: =IF($B34='Forecast 1'!$B34,INDEX('Forecast 1'!$1:$1048576,MATCH('Forecast 1'!$B34,'Forecast 1'!$B:$B,0),MATCH('Forecast 1'!V$7,'Forecast 1'!$7:$7,0)),"Mismatch") -> 0
B35: Repairs & Maintenance | C35: Enter Manually | D35: =IF($B35='Forecast 1'!$B35,INDEX('Forecast 1'!$1:$1048576,MATCH('Forecast 1'!$B35,'Forecast 1'!$B:$B,0),MATCH('Forecast 1'!D$7,'Forecast 1'!$7:$7,0)),"Mismatch") -> 0 | E35: =IF($B35='Forecast 1'!$B35,INDEX('Forecast 1'!$1:$1048576,MATCH('Forecast 1'!$B35,'Forecast 1'!$B:$B,0),MATCH('Forecast 1'!E$7,'Forecast 1'!$7:$7,0)),"Mismatch") -> 0 | F35: =IF($B35='Forecast 1'!$B35,INDEX('Forecast 1'!$1:$1048576,MATCH('Forecast 1'!$B35,'Forecast 1'!$B:$B,0),MATCH('Forecast 1'!F$7,'Forecast 1'!$7:$7,0)),"Mismatch") -> 0 | G35: =IF($B35='Forecast 1'!$B35,INDEX('Forecast 1'!$1:$1048576,MATCH('Forecast 1'!$B35,'Forecast 1'!$B:$B,0),MATCH('Forecast 1'!G$7,'Forecast 1'!$7:$7,0)),"Mismatch") -> 0 | H35: =IF($B35='Forecast 1'!$B35,INDEX('Forecast 1'!$1:$1048576,MATCH('Forecast 1'!$B35,'Forecast 1'!$B:$B,0),MATCH('Forecast 1'!H$7,'Forecast 1'!$7:$7,0)),"Mismatch") -> 0 | I35: =IF($B35='Forecast 1'!$B35,INDEX('Forecast 1'!$1:$1048576,MATCH('Forecast 1'!$B35,'Forecast 1'!$B:$B,0),MATCH('Forecast 1'!I$7,'Forecast 1'!$7:$7,0)),"Mismatch") -> 0 | J35: =IF($B35='Forecast 1'!$B35,INDEX('Forecast 1'!$1:$1048576,MATCH('Forecast 1'!$B35,'Forecast 1'!$B:$B,0),MATCH('Forecast 1'!J$7,'Forecast 1'!$7:$7,0)),"Mismatch") -> 0 | K35: =IF($B35='Forecast 1'!$B35,INDEX('Forecast 1'!$1:$1048576,MATCH('Forecast 1'!$B35,'Forecast 1'!$B:$B,0),MATCH('Forecast 1'!K$7,'Forecast 1'!$7:$7,0)),"Mismatch") -> 0 | ... V35: =IF($B35='Forecast 1'!$B35,INDEX('Forecast 1'!$1:$1048576,MATCH('Forecast 1'!$B35,'Forecast 1'!$B:$B,0),MATCH('Forecast 1'!V$7,'Forecast 1'!$7:$7,0)),"Mismatch") -> 0
B36: Supplies | C36: Enter Manually | D36: =IF($B36='Forecast 1'!$B36,INDEX('Forecast 1'!$1:$1048576,MATCH('Forecast 1'!$B36,'Forecast 1'!$B:$B,0),MATCH('Forecast 1'!D$7,'Forecast 1'!$7:$7,0)),"Mismatch") -> 0 | E36: =IF($B36='Forecast 1'!$B36,INDEX('Forecast 1'!$1:$1048576,MATCH('Forecast 1'!$B36,'Forecast 1'!$B:$B,0),MATCH('Forecast 1'!E$7,'Forecast 1'!$7:$7,0)),"Mismatch") -> 0 | F36: =IF($B36='Forecast 1'!$B36,INDEX('Forecast 1'!$1:$1048576,MATCH('Forecast 1'!$B36,'Forecast 1'!$B:$B,0),MATCH('Forecast 1'!F$7,'Forecast 1'!$7:$7,0)),"Mismatch") -> 0 | G36: =IF($B36='Forecast 1'!$B36,INDEX('Forecast 1'!$1:$1048576,MATCH('Forecast 1'!$B36,'Forecast 1'!$B:$B,0),MATCH('Forecast 1'!G$7,'Forecast 1'!$7:$7,0)),"Mismatch") -> 0 | H36: =IF($B36='Forecast 1'!$B36,INDEX('Forecast 1'!$1:$1048576,MATCH('Forecast 1'!$B36,'Forecast 1'!$B:$B,0),MATCH('Forecast 1'!H$7,'Forecast 1'!$7:$7,0)),"Mismatch") -> 0 | I36: =IF($B36='Forecast 1'!$B36,INDEX('Forecast 1'!$1:$1048576,MATCH('Forecast 1'!$B36,'Forecast 1'!$B:$B,0),MATCH('Forecast 1'!I$7,'Forecast 1'!$7:$7,0)),"Mismatch") -> 0 | J36: =IF($B36='Forecast 1'!$B36,INDEX('Forecast 1'!$1:$1048576,MATCH('Forecast 1'!$B36,'Forecast 1'!$B:$B,0),MATCH('Forecast 1'!J$7,'Forecast 1'!$7:$7,0)),"Mismatch") -> 0 | K36: =IF($B36='Forecast 1'!$B36,INDEX('Forecast 1'!$1:$1048576,MATCH('Forecast 1'!$B36,'Forecast 1'!$B:$B,0),MATCH('Forecast 1'!K$7,'Forecast 1'!$7:$7,0)),"Mismatch") -> 0 | ... V36: =IF($B36='Forecast 1'!$B36,INDEX('Forecast 1'!$1:$1048576,MATCH('Forecast 1'!$B36,'Forecast 1'!$B:$B,0),MATCH('Forecast 1'!V$7,'Forecast 1'!$7:$7,0)),"Mismatch") -> 0
B37: Licenses | C37: Enter Manually | D37: =IF($B37='Forecast 1'!$B37,INDEX('Forecast 1'!$1:$1048576,MATCH('Forecast 1'!$B37,'Forecast 1'!$B:$B,0),MATCH('Forecast 1'!D$7,'Forecast 1'!$7:$7,0)),"Mismatch") -> 0 | E37: =IF($B37='Forecast 1'!$B37,INDEX('Forecast 1'!$1:$1048576,MATCH('Forecast 1'!$B37,'Forecast 1'!$B:$B,0),MATCH('Forecast 1'!E$7,'Forecast 1'!$7:$7,0)),"Mismatch") -> 0 | F37: =IF($B37='Forecast 1'!$B37,INDEX('Forecast 1'!$1:$1048576,MATCH('Forecast 1'!$B37,'Forecast 1'!$B:$B,0),MATCH('Forecast 1'!F$7,'Forecast 1'!$7:$7,0)),"Mismatch") -> 0 | G37: =IF($B37='Forecast 1'!$B37,INDEX('Forecast 1'!$1:$1048576,MATCH('Forecast 1'!$B37,'Forecast 1'!$B:$B,0),MATCH('Forecast 1'!G$7,'Forecast 1'!$7:$7,0)),"Mismatch") -> 0 | H37: =IF($B37='Forecast 1'!$B37,INDEX('Forecast 1'!$1:$1048576,MATCH('Forecast 1'!$B37,'Forecast 1'!$B:$B,0),MATCH('Forecast 1'!H$7,'Forecast 1'!$7:$7,0)),"Mismatch") -> 0 | I37: =IF($B37='Forecast 1'!$B37,INDEX('Forecast 1'!$1:$1048576,MATCH('Forecast 1'!$B37,'Forecast 1'!$B:$B,0),MATCH('Forecast 1'!I$7,'Forecast 1'!$7:$7,0)),"Mismatch") -> 0 | J37: =IF($B37='Forecast 1'!$B37,INDEX('Forecast 1'!$1:$1048576,MATCH('Forecast 1'!$B37,'Forecast 1'!$B:$B,0),MATCH('Forecast 1'!J$7,'Forecast 1'!$7:$7,0)),"Mismatch") -> 0 | K37: =IF($B37='Forecast 1'!$B37,INDEX('Forecast 1'!$1:$1048576,MATCH('Forecast 1'!$B37,'Forecast 1'!$B:$B,0),MATCH('Forecast 1'!K$7,'Forecast 1'!$7:$7,0)),"Mismatch") -> 0 | ... V37: =IF($B37='Forecast 1'!$B37,INDEX('Forecast 1'!$1:$1048576,MATCH('Forecast 1'!$B37,'Forecast 1'!$B:$B,0),MATCH('Forecast 1'!V$7,'Forecast 1'!$7:$7,0)),"Mismatch") -> 0
... B43: Other Operating Outflows | C43: Trailing 6 Week Average | D43: =IF($B43='Forecast 1'!$B43,INDEX('Forecast 1'!$1:$1048576,MATCH('Forecast 1'!$B43,'Forecast 1'!$B:$B,0),MATCH('Forecast 1'!D$7,'Forecast 1'!$7:$7,0)),"Mismatch") -> -1270 | E43: =IF($B43='Forecast 1'!$B43,INDEX('Forecast 1'!$1:$1048576,MATCH('Forecast 1'!$B43,'Forecast 1'!$B:$B,0),MATCH('Forecast 1'!E$7,'Forecast 1'!$7:$7,0)),"Mismatch") -> -2570 | F43: =IF($B43='Forecast 1'!$B43,INDEX('Forecast 1'!$1:$1048576,MATCH('Forecast 1'!$B43,'Forecast 1'!$B:$B,0),MATCH('Forecast 1'!F$7,'Forecast 1'!$7:$7,0)),"Mismatch") -> 0 | G43: =IF($B43='Forecast 1'!$B43,INDEX('Forecast 1'!$1:$1048576,MATCH('Forecast 1'!$B43,'Forecast 1'!$B:$B,0),MATCH('Forecast 1'!G$7,'Forecast 1'!$7:$7,0)),"Mismatch") -> 0 | H43: =IF($B43='Forecast 1'!$B43,INDEX('Forecast 1'!$1:$1048576,MATCH('Forecast 1'!$B43,'Forecast 1'!$B:$B,0),MATCH('Forecast 1'!H$7,'Forecast 1'!$7:$7,0)),"Mismatch") -> 0 | I43: =IF($B43='Forecast 1'!$B43,INDEX('Forecast 1'!$1:$1048576,MATCH('Forecast 1'!$B43,'Forecast 1'!$B:$B,0),MATCH('Forecast 1'!I$7,'Forecast 1'!$7:$7,0)),"Mismatch") -> -1270 | J43: =IF($B43='Forecast 1'!$B43,INDEX('Forecast 1'!$1:$1048576,MATCH('Forecast 1'!$B43,'Forecast 1'!$B:$B,0),MATCH('Forecast 1'!J$7,'Forecast 1'!$7:$7,0)),"Mismatch") -> -851.66667 | K43: =IF($B43='Forecast 1'!$B43,INDEX('Forecast 1'!$1:$1048576,MATCH('Forecast 1'!$B43,'Forecast 1'!$B:$B,0),MATCH('Forecast 1'!K$7,'Forecast 1'!$7:$7,0)),"Mismatch") -> -781.94444 | ... V43: =IF($B43='Forecast 1'!$B43,INDEX('Forecast 1'!$1:$1048576,MATCH('Forecast 1'!$B43,'Forecast 1'!$B:$B,0),MATCH('Forecast 1'!V$7,'Forecast 1'!$7:$7,0)),"Mismatch") -> -666.46564
B46: Total Operating Cash Outflows | D46: =SUM(D24:D45) -> -114140 | E46: =SUM(E24:E45) -> -374900 | F46: =SUM(F24:F45) -> -124910 | G46: =SUM(G24:G45) -> -180410 | H46: =SUM(H24:H45) -> -66850 | I46: =SUM(I24:I45) -> -166200 | J46: =SUM(J24:J45) -> -413930 | K46: =SUM(K24:K45) -> -56198.333 | ... V46: =SUM(V24:V45) -> -272464.99
B48: Non-Operating Cash Outflows
B49: Capital Expenditures | C49: Enter Manually | D49: =IF($B49='Forecast 1'!$B49,INDEX('Forecast 1'!$1:$1048576,MATCH('Forecast 1'!$B49,'Forecast 1'!$B:$B,0),MATCH('Forecast 1'!D$7,'Forecast 1'!$7:$7,0)),"Mismatch") -> 0 | E49: =IF($B49='Forecast 1'!$B49,INDEX('Forecast 1'!$1:$1048576,MATCH('Forecast 1'!$B49,'Forecast 1'!$B:$B,0),MATCH('Forecast 1'!E$7,'Forecast 1'!$7:$7,0)),"Mismatch") -> 0 | F49: =IF($B49='Forecast 1'!$B49,INDEX('Forecast 1'!$1:$1048576,MATCH('Forecast 1'!$B49,'Forecast 1'!$B:$B,0),MATCH('Forecast 1'!F$7,'Forecast 1'!$7:$7,0)),"Mismatch") -> 0 | G49: =IF($B49='Forecast 1'!$B49,INDEX('Forecast 1'!$1:$1048576,MATCH('Forecast 1'!$B49,'Forecast 1'!$B:$B,0),MATCH('Forecast 1'!G$7,'Forecast 1'!$7:$7,0)),"Mismatch") -> 0 | H49: =IF($B49='Forecast 1'!$B49,INDEX('Forecast 1'!$1:$1048576,MATCH('Forecast 1'!$B49,'Forecast 1'!$B:$B,0),MATCH('Forecast 1'!H$7,'Forecast 1'!$7:$7,0)),"Mismatch") -> 0 | I49: =IF($B49='Forecast 1'!$B49,INDEX('Forecast 1'!$1:$1048576,MATCH('Forecast 1'!$B49,'Forecast 1'!$B:$B,0),MATCH('Forecast 1'!I$7,'Forecast 1'!$7:$7,0)),"Mismatch") -> 0 | J49: =IF($B49='Forecast 1'!$B49,INDEX('Forecast 1'!$1:$1048576,MATCH('Forecast 1'!$B49,'Forecast 1'!$B:$B,0),MATCH('Forecast 1'!J$7,'Forecast 1'!$7:$7,0)),"Mismatch") -> 0 | K49: =IF($B49='Forecast 1'!$B49,INDEX('Forecast 1'!$1:$1048576,MATCH('Forecast 1'!$B49,'Forecast 1'!$B:$B,0),MATCH('Forecast 1'!K$7,'Forecast 1'!$7:$7,0)),"Mismatch") -> 0 | ... V49: =IF($B49='Forecast 1'!$B49,INDEX('Forecast 1'!$1:$1048576,MATCH('Forecast 1'!$B49,'Forecast 1'!$B:$B,0),MATCH('Forecast 1'!V$7,'Forecast 1'!$7:$7,0)),"Mismatch") -> 0
B50: Debt Proceeds | C50: Enter Manually | D50: =IF($B50='Forecast 1'!$B50,INDEX('Forecast 1'!$1:$1048576,MATCH('Forecast 1'!$B50,'Forecast 1'!$B:$B,0),MATCH('Forecast 1'!D$7,'Forecast 1'!$7:$7,0)),"Mismatch") -> 0 | E50: =IF($B50='Forecast 1'!$B50,INDEX('Forecast 1'!$1:$1048576,MATCH('Forecast 1'!$B50,'Forecast 1'!$B:$B,0),MATCH('Forecast 1'!E$7,'Forecast 1'!$7:$7,0)),"Mismatch") -> 0 | F50: =IF($B50='Forecast 1'!$B50,INDEX('Forecast 1'!$1:$1048576,MATCH('Forecast 1'!$B50,'Forecast 1'!$B:$B,0),MATCH('Forecast 1'!F$7,'Forecast 1'!$7:$7,0)),"Mismatch") -> 0 | G50: =IF($B50='Forecast 1'!$B50,INDEX('Forecast 1'!$1:$1048576,MATCH('Forecast 1'!$B50,'Forecast 1'!$B:$B,0),MATCH('Forecast 1'!G$7,'Forecast 1'!$7:$7,0)),"Mismatch") -> 0 | H50: =IF($B50='Forecast 1'!$B50,INDEX('Forecast 1'!$1:$1048576,MATCH('Forecast 1'!$B50,'Forecast 1'!$B:$B,0),MATCH('Forecast 1'!H$7,'Forecast 1'!$7:$7,0)),"Mismatch") -> 0 | I50: =IF($B50='Forecast 1'!$B50,INDEX('Forecast 1'!$1:$1048576,MATCH('Forecast 1'!$B50,'Forecast 1'!$B:$B,0),MATCH('Forecast 1'!I$7,'Forecast 1'!$7:$7,0)),"Mismatch") -> 0 | J50: =IF($B50='Forecast 1'!$B50,INDEX('Forecast 1'!$1:$1048576,MATCH('Forecast 1'!$B50,'Forecast 1'!$B:$B,0),MATCH('Forecast 1'!J$7,'Forecast 1'!$7:$7,0)),"Mismatch") -> 0 | K50: =IF($B50='Forecast 1'!$B50,INDEX('Forecast 1'!$1:$1048576,MATCH('Forecast 1'!$B50,'Forecast 1'!$B:$B,0),MATCH('Forecast 1'!K$7,'Forecast 1'!$7:$7,0)),"Mismatch") -> 0 | ... V50: =IF($B50='Forecast 1'!$B50,INDEX('Forecast 1'!$1:$1048576,MATCH('Forecast 1'!$B50,'Forecast 1'!$B:$B,0),MATCH('Forecast 1'!V$7,'Forecast 1'!$7:$7,0)),"Mismatch") -> 0
B51: Interest Payments | C51: Enter Manually | D51: =IF($B51='Forecast 1'!$B51,INDEX('Forecast 1'!$1:$1048576,MATCH('Forecast 1'!$B51,'Forecast 1'!$B:$B,0),MATCH('Forecast 1'!D$7,'Forecast 1'!$7:$7,0)),"Mismatch") -> 0 | E51: =IF($B51='Forecast 1'!$B51,INDEX('Forecast 1'!$1:$1048576,MATCH('Forecast 1'!$B51,'Forecast 1'!$B:$B,0),MATCH('Forecast 1'!E$7,'Forecast 1'!$7:$7,0)),"Mismatch") -> 0 | F51: =IF($B51='Forecast 1'!$B51,INDEX('Forecast 1'!$1:$1048576,MATCH('Forecast 1'!$B51,'Forecast 1'!$B:$B,0),MATCH('Forecast 1'!F$7,'Forecast 1'!$7:$7,0)),"Mismatch") -> 0 | G51: =IF($B51='Forecast 1'!$B51,INDEX('Forecast 1'!$1:$1048576,MATCH('Forecast 1'!$B51,'Forecast 1'!$B:$B,0),MATCH('Forecast 1'!G$7,'Forecast 1'!$7:$7,0)),"Mismatch") -> 0 | H51: =IF($B51='Forecast 1'!$B51,INDEX('Forecast 1'!$1:$1048576,MATCH('Forecast 1'!$B51,'Forecast 1'!$B:$B,0),MATCH('Forecast 1'!H$7,'Forecast 1'!$7:$7,0)),"Mismatch") -> 0 | I51: =IF($B51='Forecast 1'!$B51,INDEX('Forecast 1'!$1:$1048576,MATCH('Forecast 1'!$B51,'Forecast 1'!$B:$B,0),MATCH('Forecast 1'!I$7,'Forecast 1'!$7:$7,0)),"Mismatch") -> 0 | J51: =IF($B51='Forecast 1'!$B51,INDEX('Forecast 1'!$1:$1048576,MATCH('Forecast 1'!$B51,'Forecast 1'!$B:$B,0),MATCH('Forecast 1'!J$7,'Forecast 1'!$7:$7,0)),"Mismatch") -> 0 | K51: =IF($B51='Forecast 1'!$B51,INDEX('Forecast 1'!$1:$1048576,MATCH('Forecast 1'!$B51,'Forecast 1'!$B:$B,0),MATCH('Forecast 1'!K$7,'Forecast 1'!$7:$7,0)),"Mismatch") -> 0 | ... V51: =IF($B51='Forecast 1'!$B51,INDEX('Forecast 1'!$1:$1048576,MATCH('Forecast 1'!$B51,'Forecast 1'!$B:$B,0),MATCH('Forecast 1'!V$7,'Forecast 1'!$7:$7,0)),"Mismatch") -> 0
B52: Principal Payments | C52: Enter Manually | D52: =IF($B52='Forecast 1'!$B52,INDEX('Forecast 1'!$1:$1048576,MATCH('Forecast 1'!$B52,'Forecast 1'!$B:$B,0),MATCH('Forecast 1'!D$7,'Forecast 1'!$7:$7,0)),"Mismatch") -> 0 | E52: =IF($B52='Forecast 1'!$B52,INDEX('Forecast 1'!$1:$1048576,MATCH('Forecast 1'!$B52,'Forecast 1'!$B:$B,0),MATCH('Forecast 1'!E$7,'Forecast 1'!$7:$7,0)),"Mismatch") -> 0 | F52: =IF($B52='Forecast 1'!$B52,INDEX('Forecast 1'!$1:$1048576,MATCH('Forecast 1'!$B52,'Forecast 1'!$B:$B,0),MATCH('Forecast 1'!F$7,'Forecast 1'!$7:$7,0)),"Mismatch") -> 0 | G52: =IF($B52='Forecast 1'!$B52,INDEX('Forecast 1'!$1:$1048576,MATCH('Forecast 1'!$B52,'Forecast 1'!$B:$B,0),MATCH('Forecast 1'!G$7,'Forecast 1'!$7:$7,0)),"Mismatch") -> 0 | H52: =IF($B52='Forecast 1'!$B52,INDEX('Forecast 1'!$1:$1048576,MATCH('Forecast 1'!$B52,'Forecast 1'!$B:$B,0),MATCH('Forecast 1'!H$7,'Forecast 1'!$7:$7,0)),"Mismatch") -> 0 | I52: =IF($B52='Forecast 1'!$B52,INDEX('Forecast 1'!$1:$1048576,MATCH('Forecast 1'!$B52,'Forecast 1'!$B:$B,0),MATCH('Forecast 1'!I$7,'Forecast 1'!$7:$7,0)),"Mismatch") -> 0 | J52: =IF($B52='Forecast 1'!$B52,INDEX('Forecast 1'!$1:$1048576,MATCH('Forecast 1'!$B52,'Forecast 1'!$B:$B,0),MATCH('Forecast 1'!J$7,'Forecast 1'!$7:$7,0)),"Mismatch") -> 0 | K52: =IF($B52='Forecast 1'!$B52,INDEX('Forecast 1'!$1:$1048576,MATCH('Forecast 1'!$B52,'Forecast 1'!$B:$B,0),MATCH('Forecast 1'!K$7,'Forecast 1'!$7:$7,0)),"Mismatch") -> 0 | ... V52: =IF($B52='Forecast 1'!$B52,INDEX('Forecast 1'!$1:$1048576,MATCH('Forecast 1'!$B52,'Forecast 1'!$B:$B,0),MATCH('Forecast 1'!V$7,'Forecast 1'!$7:$7,0)),"Mismatch") -> 0
B53: Tax Distributions | C53: Trailing 6 Week Average | D53: =IF($B53='Forecast 1'!$B53,INDEX('Forecast 1'!$1:$1048576,MATCH('Forecast 1'!$B53,'Forecast 1'!$B:$B,0),MATCH('Forecast 1'!D$7,'Forecast 1'!$7:$7,0)),"Mismatch") -> -21230 | E53: =IF($B53='Forecast 1'!$B53,INDEX('Forecast 1'!$1:$1048576,MATCH('Forecast 1'!$B53,'Forecast 1'!$B:$B,0),MATCH('Forecast 1'!E$7,'Forecast 1'!$7:$7,0)),"Mismatch") -> -24740 | F53: =IF($B53='Forecast 1'!$B53,INDEX('Forecast 1'!$1:$1048576,MATCH('Forecast 1'!$B53,'Forecast 1'!$B:$B,0),MATCH('Forecast 1'!F$7,'Forecast 1'!$7:$7,0)),"Mismatch") -> -20220 | G53: =IF($B53='Forecast 1'!$B53,INDEX('Forecast 1'!$1:$1048576,MATCH('Forecast 1'!$B53,'Forecast 1'!$B:$B,0),MATCH('Forecast 1'!G$7,'Forecast 1'!$7:$7,0)),"Mismatch") -> -14200 | H53: =IF($B53='Forecast 1'!$B53,INDEX('Forecast 1'!$1:$1048576,MATCH('Forecast 1'!$B53,'Forecast 1'!$B:$B,0),MATCH('Forecast 1'!H$7,'Forecast 1'!$7:$7,0)),"Mismatch") -> -12680 | I53: =IF($B53='Forecast 1'!$B53,INDEX('Forecast 1'!$1:$1048576,MATCH('Forecast 1'!$B53,'Forecast 1'!$B:$B,0),MATCH('Forecast 1'!I$7,'Forecast 1'!$7:$7,0)),"Mismatch") -> -12340 | J53: =IF($B53='Forecast 1'!$B53,INDEX('Forecast 1'!$1:$1048576,MATCH('Forecast 1'!$B53,'Forecast 1'!$B:$B,0),MATCH('Forecast 1'!J$7,'Forecast 1'!$7:$7,0)),"Mismatch") -> -17568.333 | K53: =IF($B53='Forecast 1'!$B53,INDEX('Forecast 1'!$1:$1048576,MATCH('Forecast 1'!$B53,'Forecast 1'!$B:$B,0),MATCH('Forecast 1'!K$7,'Forecast 1'!$7:$7,0)),"Mismatch") -> -16958.056 | ... V53: =IF($B53='Forecast 1'!$B53,INDEX('Forecast 1'!$1:$1048576,MATCH('Forecast 1'!$B53,'Forecast 1'!$B:$B,0),MATCH('Forecast 1'!V$7,'Forecast 1'!$7:$7,0)),"Mismatch") -> -15563.802
...

Sheet Forecast 1
B1: Sharpe and Sortino
B2: Master Error Check Cell | D2: =+'Error Checking'!B2 -> 0
B4: Actual / Forecast | D4: Actual | E4: Actual | F4: Actual | G4: Actual | H4: Actual | I4: Actual | J4: Forecast | K4: Forecast | L4: Forecast | M4: Forecast | N4: Forecast | O4: Forecast | P4: Forecast | Q4: Forecast | R4: Forecast | S4: Forecast | T4: Forecast | U4: Forecast | V4: Forecast
B5: Week Number | D5: 1 | E5: 2 | F5: 3 | G5: 4 | H5: 5 | I5: 6 | J5: 7 | K5: 8 | L5: 9 | M5: 10 | N5: 11 | O5: 12 | P5: 13 | Q5: 14 | R5: 15 | S5: 16 | T5: 17 | U5: 18 | V5: 19
B6: Week Beginning | D6: 45221 | E6: =+D7+1 -> 45228 | F6: =+E7+1 -> 45235 | G6: =+F7+1 -> 45242 | H6: =+G7+1 -> 45249 | I6: =+H7+1 -> 45256 | J6: =+I7+1 -> 45263 | K6: =+J7+1 -> 45270 | L6: =+K7+1 -> 45277 | ... V6: =+U7+1 -> 45347
B7: Week Ending | D7: =+D6+6 -> 45227 | E7: =+E6+6 -> 45234 | F7: =+F6+6 -> 45241 | G7: =+G6+6 -> 45248 | H7: =+H6+6 -> 45255 | I7: =+I6+6 -> 45262 | J7: =+J6+6 -> 45269 | K7: =+K6+6 -> 45276 | ... V7: =+V6+6 -> 45353
B9: Cash Balance
B10: Beginning Cash | D10: =+'Bank Statement Export'!$J$56 -> 345580 | E10: =+D12 -> 210210 | F10: =+E12 -> 174090 | G10: =+F12 -> 239110 | H10: =+G12 -> 43360 | I10: =+H12 -> 325260 | J10: =+I12 -> 215160 | K10: =+J12 -> 112041.67 | L10: =+K12 -> 156995.28 | ... V10: =+U12 -> 580273.04
B11: Change in Cash | D11: =+D60 -> -135370 | E11: =+E60 -> -36120 | F11: =+F60 -> 65020 | G11: =+G60 -> -195750 | H11: =+H60 -> 281900 | I11: =+I60 -> -110100 | J11: =+J60 -> -103118.33 | K11: =+K60 -> 44953.611 | ... V11: =+V60 -> -289083.47
B12: Ending Cash | D12: =SUM(D10:D11) -> 210210 | E12: =SUM(E10:E11) -> 174090 | F12: =SUM(F10:F11) -> 239110 | G12: =SUM(G10:G11) -> 43360 | H12: =SUM(H10:H11) -> 325260 | I12: =SUM(I10:I11) -> 215160 | J12: =SUM(J10:J11) -> 112041.67 | K12: =SUM(K10:K11) -> 156995.28 | ... V12: =SUM(V10:V11) -> 291189.57
B13: Per Bank Statement | D13: =+'Bank Statement Export'!J110 -> 210210 | E13: =+'Bank Statement Export'!J187 -> 174090 | F13: =+'Bank Statement Export'!J241 -> 239110 | G13: =+'Bank Statement Export'!J286 -> 43360 | H13: =+'Bank Statement Export'!J332 -> 325260 | I13: =+'Bank Statement Export'!J381 -> 215160
B14: Double-Check | D14: =IF(D4="Forecast",0,D13-D12) -> 0 | E14: =IF(E4="Forecast",0,E13-E12) -> 0 | F14: =IF(F4="Forecast",0,F13-F12) -> 0 | G14: =IF(G4="Forecast",0,G13-G12) -> 0 | H14: =IF(H4="Forecast",0,H13-H12) -> 0 | I14: =IF(I4="Forecast",0,I13-I12) -> 0 | J14: =IF(J4="Forecast",0,J13-J12) -> 0 | K14: =IF(K4="Forecast",0,K13-K12) -> 0 | ... V14: =IF(V4="Forecast",0,V13-V12) -> 0
B15: Last Week's Forecast
B17: Cash Inflows
B18: Invoice Revenue Receipts | D18: =SUMIFS('Bank Statement Export'!$I:$I,'Bank Statement Export'!$C:$C,'Forecast 1'!$B18,'Bank Statement Export'!$A:$A,'Forecast 1'!D$7) -> 0 | E18: =SUMIFS('Bank Statement Export'!$I:$I,'Bank Statement Export'!$C:$C,'Forecast 1'!$B18,'Bank Statement Export'!$A:$A,'Forecast 1'!E$7) -> 372100 | F18: =SUMIFS('Bank Statement Export'!$I:$I,'Bank Statement Export'!$C:$C,'Forecast 1'!$B18,'Bank Statement Export'!$A:$A,'Forecast 1'!F$7) -> 210150 | G18: =SUMIFS('Bank Statement Export'!$I:$I,'Bank Statement Export'!$C:$C,'Forecast 1'!$B18,'Bank Statement Export'!$A:$A,'Forecast 1'!G$7) -> 0 | H18: =SUMIFS('Bank Statement Export'!$I:$I,'Bank Statement Export'!$C:$C,'Forecast 1'!$B18,'Bank Statement Export'!$A:$A,'Forecast 1'!H$7) -> 361430 | I18: =SUMIFS('Bank Statement Export'!$I:$I,'Bank Statement Export'!$C:$C,'Forecast 1'!$B18,'Bank Statement Export'!$A:$A,'Forecast 1'!I$7) -> 68440 | J18: =SUMIFS('AR Aging 01'!$B:$B,'AR Aging 01'!$A:$A,'Forecast 1'!J$7) -> 330000 | K18: =SUMIFS('AR Aging 01'!$B:$B,'AR Aging 01'!$A:$A,'Forecast 1'!K$7) -> 120000 | L18: =SUMIFS('AR Aging 01'!$B:$B,'AR Aging 01'!$A:$A,'Forecast 1'!L$7) -> 454000 | M18: =SUMIFS('AR Aging 01'!$B:$B,'AR Aging 01'!$A:$A,'Forecast 1'!M$7) -> 80000 | N18: =SUMIFS('AR Aging 01'!$B:$B,'AR Aging 01'!$A:$A,'Forecast 1'!N$7) -> 100000 | O18: =SUMIFS('AR Aging 01'!$B:$B,'AR Aging 01'!$A:$A,'Forecast 1'!O$7) -> 0 | P18: =SUMIFS('AR Aging 01'!$B:$B,'AR Aging 01'!$A:$A,'Forecast 1'!P$7) -> 271800 | Q18: =SUMIFS('AR Aging 01'!$B:$B,'AR Aging 01'!$A:$A,'Forecast 1'!Q$7) -> 80000 | ... V18: =SUMIFS('AR Aging 01'!$B:$B,'AR Aging 01'!$A:$A,'Forecast 1'!V$7) -> 0
B19: Other Receipts | D19: =SUMIFS('Bank Statement Export'!$I:$I,'Bank Statement Export'!$C:$C,'Forecast 1'!$B19,'Bank Statement Export'!$A:$A,'Forecast 1'!D$7) -> 0 | E19: =SUMIFS('Bank Statement Export'!$I:$I,'Bank Statement Export'!$C:$C,'Forecast 1'!$B19,'Bank Statement Export'!$A:$A,'Forecast 1'!E$7) -> 0 | F19: =SUMIFS('Bank Statement Export'!$I:$I,'Bank Statement Export'!$C:$C,'Forecast 1'!$B19,'Bank Statement Export'!$A:$A,'Forecast 1'!F$7) -> 0 | G19: =SUMIFS('Bank Statement Export'!$I:$I,'Bank Statement Export'!$C:$C,'Forecast 1'!$B19,'Bank Statement Export'!$A:$A,'Forecast 1'!G$7) -> 0 | H19: =SUMIFS('Bank Statement Export'!$I:$I,'Bank Statement Export'!$C:$C,'Forecast 1'!$B19,'Bank Statement Export'!$A:$A,'Forecast 1'!H$7) -> 0 | I19: =SUMIFS('Bank Statement Export'!$I:$I,'Bank Statement Export'!$C:$C,'Forecast 1'!$B19,'Bank Statement Export'!$A:$A,'Forecast 1'!I$7) -> 0 | J19: =SUMIFS('Bank Statement Export'!$I:$I,'Bank Statement Export'!$C:$C,'Forecast 1'!$B19,'Bank Statement Export'!$A:$A,'Forecast 1'!J$7) -> 0 | K19: =SUMIFS('Bank Statement Export'!$I:$I,'Bank Statement Export'!$C:$C,'Forecast 1'!$B19,'Bank Statement Export'!$A:$A,'Forecast 1'!K$7) -> 0 | ... V19: =SUMIFS('Bank Statement Export'!$I:$I,'Bank Statement Export'!$C:$C,'Forecast 1'!$B19,'Bank Statement Export'!$A:$A,'Forecast 1'!V$7) -> 0
B21: Total Cash Inflows | D21: =SUM(D18:D20) -> 0 | E21: =SUM(E18:E20) -> 372100 | F21: =SUM(F18:F20) -> 210150 | G21: =SUM(G18:G20) -> 0 | H21: =SUM(H18:H20) -> 361430 | I21: =SUM(I18:I20) -> 68440 | J21: =SUM(J18:J20) -> 330000 | K21: =SUM(K18:K20) -> 120000 | ... V21: =SUM(V18:V20) -> 0
B23: Operating Cash Outflows
B24: Accounts Payable | D24: =SUMIFS('Bank Statement Export'!$I:$I,'Bank Statement Export'!$C:$C,'Forecast 1'!$B24,'Bank Statement Export'!$A:$A,'Forecast 1'!D$7) -> -33620 | E24: =SUMIFS('Bank Statement Export'!$I:$I,'Bank Statement Export'!$C:$C,'Forecast 1'!$B24,'Bank Statement Export'!$A:$A,'Forecast 1'!E$7) -> -83210 | F24: =SUMIFS('Bank Statement Export'!$I:$I,'Bank Statement Export'!$C:$C,'Forecast 1'!$B24,'Bank Statement Export'!$A:$A,'Forecast 1'!F$7) -> -69810 | G24: =SUMIFS('Bank Statement Export'!$I:$I,'Bank Statement Export'!$C:$C,'Forecast 1'!$B24,'Bank Statement Export'!$A:$A,'Forecast 1'!G$7) -> -40140 | H24: =SUMIFS('Bank Statement Export'!$I:$I,'Bank Statement Export'!$C:$C,'Forecast 1'!$B24,'Bank Statement Export'!$A:$A,'Forecast 1'!H$7) -> -18680 | I24: =SUMIFS('Bank Statement Export'!$I:$I,'Bank Statement Export'!$C:$C,'Forecast 1'!$B24,'Bank Statement Export'!$A:$A,'Forecast 1'!I$7) -> -88580 | J24: =-SUMIFS('AP Aging 01'!$B:$B,'AP Aging 01'!$A:$A,'Forecast 1'!J$7,'AP Aging 01'!$D:$D,"<>Yes") -> -800 | K24: =-SUMIFS('AP Aging 01'!$B:$B,'AP Aging 01'!$A:$A,'Forecast 1'!K$7,'AP Aging 01'!$D:$D,"<>Yes") -> -1800 | L24: =-SUMIFS('AP Aging 01'!$B:$B,'AP Aging 01'!$A:$A,'Forecast 1'!L$7,'AP Aging 01'!$D:$D,"<>Yes") -> -145800 | M24: =-SUMIFS('AP Aging 01'!$B:$B,'AP Aging 01'!$A:$A,'Forecast 1'!M$7,'AP Aging 01'!$D:$D,"<>Yes") -> 0 | N24: =-SUMIFS('AP Aging 01'!$B:$B,'AP Aging 01'!$A:$A,'Forecast 1'!N$7,'AP Aging 01'!$D:$D,"<>Yes") -> 0 | O24: =-SUMIFS('AP Aging 01'!$B:$B,'AP Aging 01'!$A:$A,'Forecast 1'!O$7,'AP Aging 01'!$D:$D,"<>Yes") -> 0 | P24: =-SUMIFS('AP Aging 01'!$B:$B,'AP Aging 01'!$A:$A,'Forecast 1'!P$7,'AP Aging 01'!$D:$D,"<>Yes") -> 0 | Q24: =-SUMIFS('AP Aging 01'!$B:$B,'AP Aging 01'!$A:$A,'Forecast 1'!Q$7,'AP Aging 01'!$D:$D,"<>Yes") -> 0 | ... V24: =-SUMIFS('AP Aging 01'!$B:$B,'AP Aging 01'!$A:$A,'Forecast 1'!V$7,'AP Aging 01'!$D:$D,"<>Yes") -> 0
B25: Credit Cards | D25: =SUMIFS('Bank Statement Export'!$I:$I,'Bank Statement Export'!$C:$C,'Forecast 1'!$B25,'Bank Statement Export'!$A:$A,'Forecast 1'!D$7) -> 0 | E25: =SUMIFS('Bank Statement Export'!$I:$I,'Bank Statement Export'!$C:$C,'Forecast 1'!$B25,'Bank Statement Export'!$A:$A,'Forecast 1'!E$7) -> -194090 | F25: =SUMIFS('Bank Statement Export'!$I:$I,'Bank Statement Export'!$C:$C,'Forecast 1'!$B25,'Bank Statement Export'!$A:$A,'Forecast 1'!F$7) -> 0 | G25: =SUMIFS('Bank Statement Export'!$I:$I,'Bank Statement Export'!$C:$C,'Forecast 1'!$B25,'Bank Statement Export'!$A:$A,'Forecast 1'!G$7) -> -100000 | H25: =SUMIFS('Bank Statement Export'!$I:$I,'Bank Statement Export'!$C:$C,'Forecast 1'!$B25,'Bank Statement Export'!$A:$A,'Forecast 1'!H$7) -> 0 | I25: =SUMIFS('Bank Statement Export'!$I:$I,'Bank Statement Export'!$C:$C,'Forecast 1'!$B25,'Bank Statement Export'!$A:$A,'Forecast 1'!I$7) -> -32000 | J25: =-SUMIFS('AP Aging 01'!$B:$B,'AP Aging 01'!$A:$A,'Forecast 1'!J$7,'AP Aging 01'!$D:$D,"Yes") -> -350000 | K25: =-SUMIFS('AP Aging 01'!$B:$B,'AP Aging 01'!$A:$A,'Forecast 1'!K$7,'AP Aging 01'!$D:$D,"Yes") -> 0 | L25: =-SUMIFS('AP Aging 01'!$B:$B,'AP Aging 01'!$A:$A,'Forecast 1'!L$7,'AP Aging 01'!$D:$D,"Yes") -> 0 | M25: =-SUMIFS('AP Aging 01'!$B:$B,'AP Aging 01'!$A:$A,'Forecast 1'!M$7,'AP Aging 01'!$D:$D,"Yes") -> 0 | N25: =-SUMIFS('AP Aging 01'!$B:$B,'AP Aging 01'!$A:$A,'Forecast 1'!N$7,'AP Aging 01'!$D:$D,"Yes") -> -55000 | O25: =-SUMIFS('AP Aging 01'!$B:$B,'AP Aging 01'!$A:$A,'Forecast 1'!O$7,'AP Aging 01'!$D:$D,"Yes") -> 0 | P25: =-SUMIFS('AP Aging 01'!$B:$B,'AP Aging 01'!$A:$A,'Forecast 1'!P$7,'AP Aging 01'!$D:$D,"Yes") -> 0 | Q25: =-SUMIFS('AP Aging 01'!$B:$B,'AP Aging 01'!$A:$A,'Forecast 1'!Q$7,'AP Aging 01'!$D:$D,"Yes") -> 0 | ... V25: =-SUMIFS('AP Aging 01'!$B:$B,'AP Aging 01'!$A:$A,'Forecast 1'!V$7,'AP Aging 01'!$D:$D,"Yes") -> -210000
B26: Payroll | C26: Trailing 6 Week Average | D26: =SUMIFS('Bank Statement Export'!$I:$I,'Bank Statement Export'!$C:$C,'Forecast 1'!$B26,'Bank Statement Export'!$A:$A,'Forecast 1'!D$7) -> -77830 | E26: =SUMIFS('Bank Statement Export'!$I:$I,'Bank Statement Export'!$C:$C,'Forecast 1'!$B26,'Bank Statement Export'!$A:$A,'Forecast 1'!E$7) -> -78050 | F26: =SUMIFS('Bank Statement Export'!$I:$I,'Bank Statement Export'!$C:$C,'Forecast 1'!$B26,'Bank Statement Export'!$A:$A,'Forecast 1'!F$7) -> -51670 | G26: =SUMIFS('Bank Statement Export'!$I:$I,'Bank Statement Export'!$C:$C,'Forecast 1'!$B26,'Bank Statement Export'!$A:$A,'Forecast 1'!G$7) -> -39960 | H26: =SUMIFS('Bank Statement Export'!$I:$I,'Bank Statement Export'!$C:$C,'Forecast 1'!$B26,'Bank Statement Export'!$A:$A,'Forecast 1'!H$7) -> -44380 | I26: =SUMIFS('Bank Statement Export'!$I:$I,'Bank Statement Export'!$C:$C,'Forecast 1'!$B26,'Bank Statement Export'!$A:$A,'Forecast 1'!I$7) -> -35340 | J26: =AVERAGE(D26:I26) -> -54538.333 | K26: =AVERAGE(E26:J26) -> -50656.389 | L26: =AVERAGE(F26:K26) -> -46090.787 | M26: =AVERAGE(G26:L26) -> -45160.918 | N26: =AVERAGE(H26:M26) -> -46027.738 | O26: =AVERAGE(I26:N26) -> -46302.361 | P26: =AVERAGE(J26:O26) -> -48129.421 | Q26: =AVERAGE(K26:P26) -> -47061.269 | ... V26: =AVERAGE(P26:U26) -> -46966.597
B27: Contractors | C27: Enter Manually | D27: =SUMIFS('Bank Statement Export'!$I:$I,'Bank Statement Export'!$C:$C,'Forecast 1'!$B27,'Bank Statement Export'!$A:$A,'Forecast 1'!D$7) -> 0 | E27: =SUMIFS('Bank Statement Export'!$I:$I,'Bank Statement Export'!$C:$C,'Forecast 1'!$B27,'Bank Statement Export'!$A:$A,'Forecast 1'!E$7) -> 0 | F27: =SUMIFS('Bank Statement Export'!$I:$I,'Bank Statement Export'!$C:$C,'Forecast 1'!$B27,'Bank Statement Export'!$A:$A,'Forecast 1'!F$7) -> 0 | G27: =SUMIFS('Bank Statement Export'!$I:$I,'Bank Statement Export'!$C:$C,'Forecast 1'!$B27,'Bank Statement Export'!$A:$A,'Forecast 1'!G$7) -> 0 | H27: =SUMIFS('Bank Statement Export'!$I:$I,'Bank Statement Export'!$C:$C,'Forecast 1'!$B27,'Bank Statement Export'!$A:$A,'Forecast 1'!H$7) -> 0 | I27: =SUMIFS('Bank Statement Export'!$I:$I,'Bank Statement Export'!$C:$C,'Forecast 1'!$B27,'Bank Statement Export'!$A:$A,'Forecast 1'!I$7) -> 0 | J27: 0 | K27: 0 | L27: 0 | M27: 0 | N27: 0 | O27: 0 | P27: 0 | Q27: 0 | R27: 0 | S27: 0 | T27: 0 | U27: 0 | V27: 0
B28: Dues & Subscriptions | C28: Trailing 6 Week Average | D28: =SUMIFS('Bank Statement Export'!$I:$I,'Bank Statement Export'!$C:$C,'Forecast 1'!$B28,'Bank Statement Export'!$A:$A,'Forecast 1'!D$7) -> -310 | E28: =SUMIFS('Bank Statement Export'!$I:$I,'Bank Statement Export'!$C:$C,'Forecast 1'!$B28,'Bank Statement Export'!$A:$A,'Forecast 1'!E$7) -> -310 | F28: =SUMIFS('Bank Statement Export'!$I:$I,'Bank Statement Export'!$C:$C,'Forecast 1'!$B28,'Bank Statement Export'!$A:$A,'Forecast 1'!F$7) -> -310 | G28: =SUMIFS('Bank Statement Export'!$I:$I,'Bank Statement Export'!$C:$C,'Forecast 1'!$B28,'Bank Statement Export'!$A:$A,'Forecast 1'!G$7) -> -310 | H28: =SUMIFS('Bank Statement Export'!$I:$I,'Bank Statement Export'!$C:$C,'Forecast 1'!$B28,'Bank Statement Export'!$A:$A,'Forecast 1'!H$7) -> -310 | I28: =SUMIFS('Bank Statement Export'!$I:$I,'Bank Statement Export'!$C:$C,'Forecast 1'!$B28,'Bank Statement Export'!$A:$A,'Forecast 1'!I$7) -> -310 | J28: =AVERAGE(D28:I28) -> -310 | K28: =AVERAGE(E28:J28) -> -310 | L28: =AVERAGE(F28:K28) -> -310 | M28: =AVERAGE(G28:L28) -> -310 | N28: =AVERAGE(H28:M28) -> -310 | O28: =AVERAGE(I28:N28) -> -310 | P28: =AVERAGE(J28:O28) -> -310 | Q28: =AVERAGE(K28:P28) -> -310 | ... V28: =AVERAGE(P28:U28) -> -310
B29: Insurance | C29: Enter Manually | D29: =SUMIFS('Bank Statement Export'!$I:$I,'Bank Statement Export'!$C:$C,'Forecast 1'!$B29,'Bank Statement Export'!$A:$A,'Forecast 1'!D$7) -> 0 | E29: =SUMIFS('Bank Statement Export'!$I:$I,'Bank Statement Export'!$C:$C,'Forecast 1'!$B29,'Bank Statement Export'!$A:$A,'Forecast 1'!E$7) -> 0 | F29: =SUMIFS('Bank Statement Export'!$I:$I,'Bank Statement Export'!$C:$C,'Forecast 1'!$B29,'Bank Statement Export'!$A:$A,'Forecast 1'!F$7) -> 0 | G29: =SUMIFS('Bank Statement Export'!$I:$I,'Bank Statement Export'!$C:$C,'Forecast 1'!$B29,'Bank Statement Export'!$A:$A,'Forecast 1'!G$7) -> 0 | H29: =SUMIFS('Bank Statement Export'!$I:$I,'Bank Statement Export'!$C:$C,'Forecast 1'!$B29,'Bank Statement Export'!$A:$A,'Forecast 1'!H$7) -> 0 | I29: =SUMIFS('Bank Statement Export'!$I:$I,'Bank Statement Export'!$C:$C,'Forecast 1'!$B29,'Bank Statement Export'!$A:$A,'Forecast 1'!I$7) -> 0 | J29: =SUMIFS('Bank Statement Export'!$I:$I,'Bank Statement Export'!$C:$C,'Forecast 1'!$B29,'Bank Statement Export'!$A:$A,'Forecast 1'!J$7) -> 0 | K29: =SUMIFS('Bank Statement Export'!$I:$I,'Bank Statement Export'!$C:$C,'Forecast 1'!$B29,'Bank Statement Export'!$A:$A,'Forecast 1'!K$7) -> 0 | ... V29: =SUMIFS('Bank Statement Export'!$I:$I,'Bank Statement Export'!$C:$C,'Forecast 1'!$B29,'Bank Statement Export'!$A:$A,'Forecast 1'!V$7) -> 0
B30: Lease Payments | C30: Trailing 6 Week Average | D30: =SUMIFS('Bank Statement Export'!$I:$I,'Bank Statement Export'!$C:$C,'Forecast 1'!$B30,'Bank Statement Export'!$A:$A,'Forecast 1'!D$7) -> 0 | E30: =SUMIFS('Bank Statement Export'!$I:$I,'Bank Statement Export'!$C:$C,'Forecast 1'!$B30,'Bank Statement Export'!$A:$A,'Forecast 1'!E$7) -> -1350 | F30: =SUMIFS('Bank Statement Export'!$I:$I,'Bank Statement Export'!$C:$C,'Forecast 1'!$B30,'Bank Statement Export'!$A:$A,'Forecast 1'!F$7) -> 0 | G30: =SUMIFS('Bank Statement Export'!$I:$I,'Bank Statement Export'!$C:$C,'Forecast 1'!$B30,'Bank Statement Export'!$A:$A,'Forecast 1'!G$7) -> 0 | H30: =SUMIFS('Bank Statement Export'!$I:$I,'Bank Statement Export'!$C:$C,'Forecast 1'!$B30,'Bank Statement Export'!$A:$A,'Forecast 1'!H$7) -> -1350 | I30: =SUMIFS('Bank Statement Export'!$I:$I,'Bank Statement Export'!$C:$C,'Forecast 1'!$B30,'Bank Statement Export'!$A:$A,'Forecast 1'!I$7) -> -1350 | J30: =AVERAGE(D30:I30) -> -675 | K30: =AVERAGE(E30:J30) -> -787.5 | L30: =AVERAGE(F30:K30) -> -693.75 | M30: =AVERAGE(G30:L30) -> -809.375 | N30: =AVERAGE(H30:M30) -> -944.27083 | O30: =AVERAGE(I30:N30) -> -876.64931 | P30: =AVERAGE(J30:O30) -> -797.75752 | Q30: =AVERAGE(K30:P30) -> -818.21711 | ... V30: =AVERAGE(P30:U30) -> -828.39988
B31: Marketing | C31: Trailing 6 Week Average | D31: =SUMIFS('Bank Statement Export'!$I:$I,'Bank Statement Export'!$C:$C,'Forecast 1'!$B31,'Bank Statement Export'!$A:$A,'Forecast 1'!D$7) -> 0 | E31: =SUMIFS('Bank Statement Export'!$I:$I,'Bank Statement Export'!$C:$C,'Forecast 1'!$B31,'Bank Statement Export'!$A:$A,'Forecast 1'!E$7) -> -1510 | F31: =SUMIFS('Bank Statement Export'!$I:$I,'Bank Statement Export'!$C:$C,'Forecast 1'!$B31,'Bank Statement Export'!$A:$A,'Forecast 1'!F$7) -> -1020 | G31: =SUMIFS('Bank Statement Export'!$I:$I,'Bank Statement Export'!$C:$C,'Forecast 1'!$B31,'Bank Statement Export'!$A:$A,'Forecast 1'!G$7) -> 0 | H31: =SUMIFS('Bank Statement Export'!$I:$I,'Bank Statement Export'!$C:$C,'Forecast 1'!$B31,'Bank Statement Export'!$A:$A,'Forecast 1'!H$7) -> 0 | I31: =SUMIFS('Bank Statement Export'!$I:$I,'Bank Statement Export'!$C:$C,'Forecast 1'!$B31,'Bank Statement Export'!$A:$A,'Forecast 1'!I$7) -> -1510 | J31: =AVERAGE(D31:I31) -> -673.33333 | K31: =AVERAGE(E31:J31) -> -785.55556 | L31: =AVERAGE(F31:K31) -> -664.81481 | M31: =AVERAGE(G31:L31) -> -605.61728 | N31: =AVERAGE(H31:M31) -> -706.5535 | O31: =AVERAGE(I31:N31) -> -824.31241 | P31: =AVERAGE(J31:O31) -> -710.03115 | Q31: =AVERAGE(K31:P31) -> -716.14745 | ... V31: =AVERAGE(P31:U31) -> -717.21397
